Traceback (most recent call last):
  File "/home/eliasd/lensing/pyrofit-lensing-analysis/experiments/swyft_subhalo_3/train.py", line 92, in <module>
    run()
  File "/home/eliasd/.pyenv/versions/lens-3.9.7/lib/python3.9/site-packages/click/core.py", line 1137, in __call__
    return self.main(*args, **kwargs)
  File "/home/eliasd/.pyenv/versions/lens-3.9.7/lib/python3.9/site-packages/click/core.py", line 1062, in main
    rv = self.invoke(ctx)
  File "/home/eliasd/.pyenv/versions/lens-3.9.7/lib/python3.9/site-packages/click/core.py", line 1404, in invoke
    return ctx.invoke(self.callback, **ctx.params)
  File "/home/eliasd/.pyenv/versions/lens-3.9.7/lib/python3.9/site-packages/click/core.py", line 763, in invoke
    return __callback(*args, **kwargs)
  File "/home/eliasd/lensing/pyrofit-lensing-analysis/experiments/swyft_subhalo_3/train.py", line 45, in run
    assert os.path.exists(f'/nfs/scratch/eliasd/store{RUN}.sync')
AssertionError
